<?xml version="1.0"?>

<robot xmlns:xacro="http://ros.org/wiki/xacro">

  <xacro:include filename="$(find warehouse_simulation)/urdf/pioneer3dx_wheel.xacro"/>

  <!-- Chassis description -->
  <link name="base_link">
  <!-- CHECK THESE VALUES. THEY MAY BE COMPLETELY WRONG. -->
  <inertial>
    <mass value="40.0"/>
    <origin xyz="-0.045 0 0.148"/>
    <inertia ixx="0.3338" ixy="0.0" ixz="0.0"
         iyy="0.4783" iyz="0.0"
         izz="0.3338"/>
  </inertial>
  <!-- The base visual is fine. Just the inertial is questionable.-->
  <visual>
    <origin xyz="-0.045 0 0.148" rpy="0 0 0"/>
    <geometry name="pioneer_geom">
    <mesh filename="package://warehouse_simulation/meshes/chassis.stl"/>
    </geometry>
    <material name="ChassisRed">
    <color rgba="0.851 0.0 0.0 1.0"/>
    </material>
  </visual>
  <collision>
    <origin xyz="-0.045 0 0.148" rpy="0 0 0"/>
    <geometry>
        <box size="0.4 0.28 0.17"/>
    </geometry>
  </collision>
  </link>
  <gazebo reference="base_link">
  <material value="Gazebo/Red"/>
  </gazebo>

  <link name="top_plate">
  <inertial>
    <mass value="0.01"/>  
    <origin xyz="0 0 0"/>
    <inertia ixx="1" ixy="0" ixz="0"
         iyy="1" iyz="0"
         izz="1"/>
  </inertial>
  <visual>
    <origin xyz="0 0 0" rpy="0 0 0"/>
    <geometry name="pioneer_geom">
    <mesh filename="package://warehouse_simulation/meshes/top.stl"/>
    </geometry>
    <material name="TopBlack">
    <color rgba="0.038 0.038 0.038 1.0"/>
    </material>
  </visual>
  </link>
  <gazebo reference="top_plate">
  <material value="Gazebo/Black"/>
  </gazebo>

  <joint name="base_top_joint" type="fixed">
  <origin xyz="-0.045 0 0.24" rpy="0 0 0"/>
  <parent link="base_link"/>
  <child link="top_plate"/>
  </joint>

  <!-- Swivel -->
  <link name="swivel">
  <inertial>
    <mass value="0.1"/> 
    <origin xyz="0 0 0"/>
    <inertia ixx="0.01" ixy="0" ixz="0"
         iyy="0.01" iyz="0" izz="0.01"/>
    </inertial>
  <visual>
    <origin xyz="0 0 0" rpy="0 0 0"/>
    <geometry name="pioneer_geom">
    <mesh filename="package://warehouse_simulation/meshes/swivel.stl"/>
    </geometry>
    <material name="swivel">
    <color rgba="0.5 0.5 0.5 1"/>
    </material>
  </visual>
  </link>
  <gazebo reference="swivel">
  <material value="Gazebo/Black"/>
  </gazebo>

  <joint name="base_swivel_joint" type="continuous">
  <origin xyz="-0.185 0 0.055" rpy="0 0 0"/>
  <axis xyz="0 0 1"/>
    <limit effort="100" velocity="100" k_velocity="0" />
    <joint_properties damping="0.0" friction="0.0" />
  <parent link="base_link"/>
  <child link="swivel"/>
  </joint>

  <!-- Center Wheel + Hubcap -->
  <link name="center_hubcap">
    <inertial>
    <mass value="0.01"/>  
    <origin xyz="0 0 0"/>
    <inertia ixx="0.012411765597" ixy="-0.000711733678" ixz="0.00050272983"
         iyy="0.015218160428" iyz="-0.000004273467" izz="0.011763977943"/>
    </inertial>
  <visual>
    <origin xyz="0 0 0" rpy="0 0 0"/>
    <geometry name="pioneer_geom">
    <mesh filename="package://warehouse_simulation/meshes/center_hubcap.stl"/>
    </geometry>
    <material name="swivel">
    <color rgba="0.5 0.5 0.5 1"/>
    </material>
  </visual>
  </link>
  <gazebo reference="center_hubcap">
  <material value="Gazebo/Black"/>
  </gazebo>

  <joint name="swivel_hubcap_joint" type="continuous">
  <origin xyz="-0.026 0 -0.016" rpy="0 0 0"/>
  <axis xyz="0 1 0"/>
  <anchor xyz="0 0 0"/>
    <limit effort="100" velocity="100" k_velocity="0" />
    <joint_properties damping="0.0" friction="0.0" />
  <parent link="swivel"/>
  <child link="center_wheel"/>
  </joint>

  <link name="center_wheel">
  <inertial>
    <mass value="0.1"/> 
    <origin xyz="0 0 0"/>
    <inertia ixx="0.012411765597" ixy="-0.000711733678" ixz="0.00050272983"
         iyy="0.015218160428" iyz="-0.000004273467" izz="0.011763977943"/>
    </inertial>
  <visual>
    <origin xyz="0 0 0" rpy="0 0 0"/>
    <geometry name="pioneer_geom">
    <mesh filename="package://warehouse_simulation/meshes/center_wheel.stl"/>
    </geometry>
    <material name="WheelBlack">
    <color rgba="0.117 0.117 0.117 1"/>
    </material>
  </visual>
  <collision>
    <origin xyz="0 0 0" rpy="${-3.1415927/2.0} 0 0"/>
    <geometry>
    <cylinder radius="0.0375" length="0.0314"/>
    </geometry>
  </collision>
  </link>
  <gazebo reference="center_wheel">
  <material value="Gazebo/Black"/>
  </gazebo>

  <joint name="center_wheel_joint" type="fixed">
  <origin xyz="-0.0035 0 -0.001" rpy="0 0 0"/>
  <parent link="center_wheel"/>
  <child link="center_hubcap"/>
  </joint>

  <xacro:p3dx_wheel suffix="left" parent="base_link" reflect="1"/>
  <xacro:p3dx_wheel suffix="right" parent="base_link" reflect="-1"/>

  <!-- Front + Back Sonar -->
  <link name="front_sonar">
  <inertial>
    <mass value="0.0001"/>  
    <origin xyz="0 0 0"/>
    <inertia ixx="1" ixy="0" ixz="0"
         iyy="1" iyz="0" izz="1"/>
  </inertial>
  <visual>
    <origin xyz="0 0 0" rpy="0 0 0"/>
    <geometry name="pioneer_geom">
    <mesh filename="package://warehouse_simulation/meshes/front_sonar.stl"/>
    </geometry>
    <material name="SonarYellow">
    <color rgba="0.715 0.583 0.210 1.0"/>
    </material>
  </visual>
  </link>
  <gazebo reference="front_sonar">
  <material value="Gazebo/Yellow"/>
  </gazebo>

  <joint name="base_front_joint" type="fixed">
  <origin xyz="-0.198 0 0.208" rpy="0 0 0"/>
  <parent link="base_link"/>
  <child link="front_sonar"/>
  </joint>

  <link name="back_sonar">
  <inertial>
    <mass value="0.0001"/>  
    <origin xyz="0 0 0"/>
    <inertia ixx="1" ixy="0" ixz="0"
         iyy="1" iyz="0" izz="1"/>
  </inertial>
  <visual>
    <origin xyz="0 0 0" rpy="0 0 0"/>
    <geometry name="pioneer_geom">
    <mesh filename="package://warehouse_simulation/meshes/back_sonar.stl"/>
    </geometry>
    <material name="SonarYellow">
    <color rgba="0.715 0.583 0.210 1.0"/>
    </material>
  </visual>
  </link>

  <gazebo reference="back_sonar">
  <material value="Gazebo/Yellow"/>
  </gazebo>

  <joint name="base_back_joint" type="fixed">
  <origin xyz="0.109 0 0.209" rpy="0 0 0"/>
  <!-- <origin xyz="0 0 0" rpy="0 0 0"/> -->
  <parent link="base_link"/>
  <child link="back_sonar"/>
  </joint>


  <!-- Imu -->
  <link name="imu_link"/>
  <joint name="base_to_imu" type="fixed">
    <axis rpy="0 0 0" xyz="0 0 0"/>
    <parent link="base_link"/>
    <child link="imu_link"/>
    <origin rpy="0 0 0" xyz="0 0 0.2"/>
  </joint>
  <gazebo reference="imu_link">
    <gravity>true</gravity>
    <sensor name="imu_sensor" type="imu">
      <always_on>true</always_on>
      <update_rate>10</update_rate>
      <visualize>true</visualize>
      <topic>imu</topic>
      <plugin filename="libgazebo_ros_imu_sensor.so" name="imu_plugin">
        <topicName>imu</topicName>
        <bodyName>imu_link</bodyName>
        <updateRateHZ>20.0</updateRateHZ>
        <gaussianNoise>0.0</gaussianNoise>
        <xyzOffset>0 0 0</xyzOffset>
        <rpyOffset>0 0 0</rpyOffset>
        <frameName>imu_link</frameName>
      </plugin>
      <pose>0 0 0 0 0 0</pose>
    </sensor>
  </gazebo>
 

 <!--_LIDAR -->
  <gazebo reference="laser">
    <material>Gazebo/FlatBlack</material>
    <sensor type="ray" name="lds_lfcd_sensor">
      <pose>0 0 0 0 0 0</pose>
      <visualize>false</visualize>
      <update_rate>5</update_rate>
      <ray>
        <scan>
          <horizontal>
            <samples>360</samples>
            <resolution>1</resolution>
            <min_angle>0.0</min_angle>
            <max_angle>6.28319</max_angle>
          </horizontal>
        </scan>
        <range>
          <min>0.120</min>
          <max>10.0</max>
          <resolution>0.050</resolution>
        </range>
        <noise>
          <type>gaussian</type>
          <mean>0.0</mean>
          <stddev>0.01</stddev>
        </noise>
      </ray>
      <plugin name="gazebo_ros_lds_lfcd_controller" filename="libgazebo_ros_laser.so">
        <topicName>scan</topicName>
        <frameName>laser</frameName>
      </plugin>
    </sensor>
  </gazebo>
 
  <joint name="scan_joint" type="fixed">
    <parent link="base_link"/>
    <child link="laser"/>
    <origin xyz="0 0 0.30" rpy="0 0 0"/>
  </joint>

  <link name="laser">
    <visual>
      <origin xyz="0 0 0.0" rpy="0 0 0"/>
      <geometry>
        <mesh filename="package://warehouse_simulation/meshes/lds.stl" scale="0.001 0.001 0.001"/>
      </geometry>
      <material name="dark"/>
    </visual>

    <collision>
      <origin xyz="0.015 0 -0.0065" rpy="0 0 0"/>
      <geometry>
        <cylinder length="0.0315" radius="0.055"/>
      </geometry>
    </collision>

    <inertial>
      <mass value="0.114" />
      <origin xyz="0 0 0" />
      <inertia ixx="0.001" ixy="0.0" ixz="0.0"
               iyy="0.001" iyz="0.0"
               izz="0.001" />
    </inertial>
  </link>


<!-- Robot locomotion plugin -->
  <gazebo>
    <plugin name="differential_drive_controller" filename="libgazebo_ros_diff_drive.so">
        <legacyMode>false</legacyMode>
        <alwaysOn>true</alwaysOn>
      <updateRate>100.0</updateRate>
      <leftJoint>base_left_wheel_joint</leftJoint>
        <rightJoint>base_right_wheel_joint</rightJoint>
      <wheelSeparation>0.32</wheelSeparation>
      <wheelDiameter>0.18</wheelDiameter>
      <wheelTorque>5</wheelTorque>
        <wheelAcceleration>0</wheelAcceleration>
        <robotNamespace>/</robotNamespace>
      <commandTopic>cmd_vel</commandTopic>
      <odometryTopic>odom</odometryTopic>
        <odometrySource>world</odometrySource><!--Other option is World or ENCODER-->
      <odometryFrame>odom</odometryFrame>
        <robotBaseFrame>base_link</robotBaseFrame>
        <publishTf>1</publishTf>
        <publishWheelTF>false</publishWheelTF>
        <publishOdomTF>true</publishOdomTF>
        <publishWheelJointState>false</publishWheelJointState>
        <rosDebugLevel>Warn</rosDebugLevel>
    </plugin>

    <!-- Fake localization plugin -->
    <plugin name="ground_truth_odometry" filename="libgazebo_ros_p3d.so">
      <alwaysOn>true</alwaysOn>
      <updateRate>100.0</updateRate>
      <bodyName>base_link</bodyName>
      <topicName>base_pose_ground_truth</topicName>
      <gaussianNoise>0.01</gaussianNoise>
      <frameName>map</frameName>-->
        <!-- initialize odometry for fake localization-->
      <xyzOffsets>0 0 0</xyzOffsets>
      <rpyOffsets>0 0 0</rpyOffsets>
    </plugin>

  </gazebo>

</robot>